File: Dynamic_1_D10_enthalpy_2kmin.csv
#EXPORTTYPE:                 ;DATA ALL
#FILE:                       ;D10_enthalpy_2kmin_Tg.ngb-sdg
#FORMAT:                     ;NETZSCH5
#FTYPE:                      ;ASCII
#IDENTITY:                   ;D10_enthalpy_2kmin_Tg
#DECIMAL:                    ;POINT
#SEPARATOR:                  ;SEMICOLON
#MTYPE:                      ;TMDSC
#MSUBTYPE:                   ;DSC(raw)
#INSTRUMENT:                 ;NETZSCH DSC 214
#PROJECT:                    ;PhD_jkjjo
#DATE/TIME:                  ;16-05-2023 14:49:39 (UTC+2)
#CORR. FILE:                 ;
#TEMPCAL:                    ;applied
#SENSITIVITY:                ;applied
#LABORATORY:                 ;DTU Wind COM
#OPERATOR:                   ;Jesper
#REMARK:                     ;SW2519-1BS1A - Enthalpy of fusion + Tg_inf
#SAMPLE:                     ;D10
#SAMPLE MASS /mg:            ;19.2
#MATERIAL:                   ;Epoxy
#REFERENCE:                  ;Empty Pan
#REFERENCE MASS /mg:         ;0
#TYPE OF CRUCIBLE:           ;Concavus Pan Al, pierced lid
#SAMPLE CRUCIBLE MASS /mg:   ;50.7
#REFERENCE CRUCIBLE MASS /mg:;51.1
#M.RANGE /‘V:                ;5000
#TAU-R:                      ;---
#CORR. CODE:                 ;000
#EXO:                        ;-1
#RANGE:                      ;-40›C..280›C/-50.0..2.0K/min-M/30/0.0..0.4
#SEGMENT:                    ;S1-6/6
#SEG. 1:                     ;25›C/5.0(K/min)/-40›C
#SEG. 2:                     ;-40›C/00:05/-40›C
#SEG. 3:                     ;-40›C/2.0(K/min)/280›C
#SEG. 4:                     ;280›C/50.0(K/min)/20›C
#SEG. 5:                     ;20›C/00:01/20›C
#SEG. 6:                     ;20›C/2.0(K/min)/280›C-M/30/0.4

##Temp./›C;Time/min;DSC/(mW/mg);Sensit./(uV/mW);Segment
 25.05900;  0.00000; 1.377704e-002;3.63056;1
 23.52900;  0.31500;      -0.10703;3.63038;1
 21.80800;  0.63000;      -0.15107;3.63010;1
 20.29200;  0.94500;      -0.13602;3.62979;1
 18.68300;  1.26000;      -0.14198;3.62940;1
 17.11200;  1.57500;      -0.13931;3.62895;1
 15.53000;  1.89000;      -0.13965;3.62844;1
 13.94900;  2.20500;      -0.13920;3.62787;1
 12.37600;  2.52000;      -0.13797;3.62723;1
 10.79900;  2.83500;      -0.13794;3.62653;1
  9.23100;  3.15000;      -0.13699;3.62577;1
  7.65200;  3.46500;      -0.13704;3.62493;1
  6.07500;  3.78000;      -0.13669;3.62404;1
  4.49900;  4.09500;      -0.13597;3.62308;1
  2.92400;  4.41000;      -0.13568;3.62205;1
  1.34700;  4.72500;      -0.13534;3.62096;1
 -0.22700;  5.04000;      -0.13510;3.61981;1
 -1.79900;  5.35500;      -0.13428;3.61859;1
 -3.37800;  5.67000;      -0.13444;3.61730;1
 -4.95100;  5.98500;      -0.13389;3.61596;1
 -6.52600;  6.30000;      -0.13349;3.61454;1
 -8.10300;  6.61500;      -0.13310;3.61305;1
 -9.67700;  6.93000;      -0.13288;3.61151;1
-11.25400;  7.24500;      -0.13233;3.60989;1
-12.82700;  7.56000;      -0.13189;3.60821;1
-14.40300;  7.87500;      -0.13182;3.60646;1
-15.97900;  8.19000;      -0.13123;3.60464;1
-17.55400;  8.50500;      -0.13099;3.60276;1
-19.12900;  8.82000;      -0.13059;3.60081;1
-20.70700;  9.13500;      -0.13035;3.59879;1
-22.27800;  9.45000;      -0.12954;3.59671;1
-23.85200;  9.76500;      -0.12936;3.59456;1
-25.43000; 10.08000;      -0.12913;3.59234;1
-27.00500; 10.39500;      -0.12856;3.59005;1
-28.57700; 10.71000;      -0.12818;3.58770;1
-30.15600; 11.02500;      -0.12790;3.58528;1
-31.72900; 11.34000;      -0.12763;3.58279;1
-33.30400; 11.65500;      -0.12710;3.58024;1
-34.87800; 11.97000;      -0.12674;3.57761;1
-36.45400; 12.28500;      -0.12639;3.57492;1
-38.03100; 12.60000;      -0.12597;3.57216;1
-39.60900; 12.91500;      -0.12566;3.56933;1
-39.99800; 13.93500; 1.233635e-002;3.56862;2
-40.00000; 15.19500; 1.318237e-002;3.56861;2
-39.99900; 16.45500; 1.233623e-002;3.56862;2
-40.00000; 17.71500; 1.184617e-002;3.56861;2
-39.35300; 18.32333; 5.502483e-002;3.56979;3
-38.51100; 18.74333; 6.417650e-002;3.57130;3
-37.65800; 19.16333; 6.610372e-002;3.57282;3
-36.82100; 19.58333; 6.468187e-002;3.57428;3
-35.98200; 20.00333; 6.433966e-002;3.57573;3
-35.14100; 20.42333; 6.468699e-002;3.57717;3
-34.30400; 20.84333; 6.580018e-002;3.57858;3
-33.46100; 21.26333; 6.742400e-002;3.57998;3
-32.62300; 21.68333; 6.893550e-002;3.58135;3
-31.78200; 22.10333; 7.080143e-002;3.58271;3
-30.94200; 22.52333; 7.233362e-002;3.58404;3
-30.10400; 22.94333; 7.377622e-002;3.58536;3
-29.26300; 23.36333; 7.517413e-002;3.58666;3
-28.42300; 23.78333; 7.606189e-002;3.58794;3
-27.58400; 24.20333; 7.690505e-002;3.58920;3
-26.74100; 24.62333; 7.753814e-002;3.59044;3
-25.90200; 25.04333; 7.846954e-002;3.59166;3
-25.06300; 25.46333; 7.954452e-002;3.59286;3
-24.22300; 25.88333; 7.951368e-002;3.59404;3
-23.38200; 26.30333; 7.859917e-002;3.59521;3
-22.54100; 26.72333; 7.656970e-002;3.59636;3
-21.70200; 27.14333; 7.467429e-002;3.59748;3
-20.86400; 27.56333; 7.395081e-002;3.59858;3
-20.02300; 27.98333; 7.584469e-002;3.59967;3
-19.18300; 28.40333; 7.492365e-002;3.60074;3
-18.34300; 28.82333; 7.315406e-002;3.60179;3
-17.50300; 29.24333; 7.215792e-002;3.60282;3
-16.66300; 29.66333; 7.183533e-002;3.60383;3
-15.82200; 30.08333; 7.200943e-002;3.60482;3
-14.98200; 30.50333; 7.206250e-002;3.60580;3
-14.14200; 30.92333; 7.206083e-002;3.60675;3
-13.30300; 31.34333; 7.203741e-002;3.60769;3
-12.46300; 31.76333; 7.201449e-002;3.60860;3
-11.62200; 32.18333; 7.203609e-002;3.60950;3
-10.78200; 32.60333; 7.198091e-002;3.61038;3
 -9.94200; 33.02333; 7.194814e-002;3.61124;3
 -9.10200; 33.44333; 7.212478e-002;3.61208;3
 -8.26200; 33.86333; 7.211475e-002;3.61290;3
 -7.42300; 34.28333; 7.206100e-002;3.61370;3
 -6.58200; 34.70333; 7.219476e-002;3.61449;3
 -5.74300; 35.12333; 7.229564e-002;3.61525;3
 -4.90200; 35.54333; 7.205642e-002;3.61600;3
 -4.06200; 35.96333; 7.209222e-002;3.61673;3
 -3.22300; 36.38333; 7.215026e-002;3.61743;3
 -2.38300; 36.80333; 7.213186e-002;3.61812;3
 -1.54300; 37.22333; 7.209189e-002;3.61880;3
 -0.70300; 37.64333; 7.221698e-002;3.61945;3
  0.13500; 38.06333; 7.192506e-002;3.62008;3
  0.97600; 38.48333; 7.207295e-002;3.62070;3
  1.81800; 38.90333; 7.211152e-002;3.62130;3
  2.65700; 39.32333; 7.212819e-002;3.62187;3
  3.49500; 39.74333; 7.198055e-002;3.62243;3
  4.33900; 40.16333; 7.248111e-002;3.62298;3
  5.17600; 40.58333; 7.198317e-002;3.62350;3
  6.01600; 41.00333; 7.210011e-002;3.62400;3
  6.85600; 41.42333; 7.194329e-002;3.62449;3
  7.69700; 41.84333; 7.206105e-002;3.62496;3
  8.53800; 42.26333; 7.202569e-002;3.62541;3
  9.37600; 42.68333; 7.178213e-002;3.62584;3
 10.21600; 43.10333; 7.176935e-002;3.62625;3
 11.05700; 43.52333; 7.184470e-002;3.62665;3
 11.89500; 43.94333; 7.176666e-002;3.62702;3
 12.73800; 44.36333; 7.196344e-002;3.62738;3
 13.57700; 44.78333; 7.183148e-002;3.62772;3
 14.41500; 45.20333; 7.159025e-002;3.62804;3
 15.25800; 45.62333; 7.193045e-002;3.62835;3
 16.09500; 46.04333; 7.167890e-002;3.62863;3
 16.93600; 46.46333; 7.169102e-002;3.62890;3
 17.77700; 46.88333; 7.174729e-002;3.62915;3
 18.61600; 47.30333; 7.157375e-002;3.62938;3
 19.45700; 47.72333; 7.179495e-002;3.62959;3
 20.29600; 48.14333; 7.147982e-002;3.62979;3
 21.13500; 48.56333; 7.112129e-002;3.62997;3
 21.97800; 48.98333; 7.167216e-002;3.63013;3
 22.81500; 49.40333; 7.110614e-002;3.63027;3
 23.65700; 49.82333; 7.093515e-002;3.63040;3
 24.49800; 50.24333; 7.103802e-002;3.63050;3
 25.33800; 50.66333; 7.083466e-002;3.63059;3
 26.17600; 51.08333; 7.050007e-002;3.63066;3
 27.01600; 51.50333; 7.038497e-002;3.63072;3
 27.85600; 51.92333; 7.009510e-002;3.63075;3
 28.69600; 52.34333; 6.986029e-002;3.63077;3
 29.53700; 52.76333; 6.960406e-002;3.63077;3
 30.37400; 53.18333; 6.926011e-002;3.63076;3
 31.21400; 53.60333; 6.880741e-002;3.63072;3
 32.05600; 54.02333; 6.883686e-002;3.63067;3
 32.89600; 54.44333; 6.877882e-002;3.63060;3
 33.73700; 54.86333; 6.822870e-002;3.63052;3
 34.57700; 55.28333; 6.794144e-002;3.63042;3
 35.41400; 55.70333; 6.726005e-002;3.63030;3
 36.25800; 56.12333; 6.735701e-002;3.63016;3
 37.09500; 56.54333; 6.635873e-002;3.63000;3
 37.93400; 56.96333; 6.593018e-002;3.62983;3
 38.77700; 57.38333; 6.565569e-002;3.62964;3
 39.61600; 57.80333; 6.481164e-002;3.62944;3
 40.45900; 58.22333; 6.441722e-002;3.62922;3
 41.29500; 58.64333; 6.351846e-002;3.62898;3
 42.13500; 59.06333; 6.280655e-002;3.62872;3
 42.97600; 59.48333; 6.240159e-002;3.62845;3
 43.81600; 59.90333; 6.148197e-002;3.62816;3
 44.65900; 60.32333; 6.072718e-002;3.62785;3
 45.49700; 60.74333; 5.969802e-002;3.62753;3
 46.33600; 61.16333; 5.851572e-002;3.62719;3
 47.17900; 61.58333; 5.788179e-002;3.62683;3
 48.01700; 62.00333; 5.634883e-002;3.62646;3
 48.85400; 62.42333; 5.518826e-002;3.62607;3
 49.69800; 62.84333; 5.435741e-002;3.62566;3
 50.53700; 63.26333; 5.306559e-002;3.62524;3
 51.37600; 63.68333; 5.160927e-002;3.62480;3
 52.21500; 64.10333; 5.002125e-002;3.62435;3
 53.05700; 64.52333; 4.860890e-002;3.62387;3
 53.89600; 64.94333; 4.679022e-002;3.62339;3
 54.73800; 65.36333; 4.537748e-002;3.62288;3
 55.57700; 65.78333; 4.351438e-002;3.62236;3
 56.41800; 66.20333; 4.167314e-002;3.62183;3
 57.25500; 66.62333; 3.946888e-002;3.62128;3
 58.09600; 67.04333; 3.711101e-002;3.62071;3
 58.93700; 67.46333; 3.471962e-002;3.62012;3
 59.77600; 67.88333; 3.249200e-002;3.61952;3
 60.61600; 68.30333; 2.984667e-002;3.61891;3
 61.45600; 68.72333; 2.705779e-002;3.61828;3
 62.29600; 69.14333; 2.397147e-002;3.61763;3
 63.13700; 69.56333; 2.091722e-002;3.61697;3
 63.97500; 69.98333; 1.748794e-002;3.61629;3
 64.81600; 70.40333; 1.411278e-002;3.61560;3
 65.65600; 70.82333; 1.026356e-002;3.61489;3
 66.49800; 71.24333; 6.600025e-003;3.61416;3
 67.33500; 71.66333; 1.889691e-003;3.61342;3
 68.17800; 72.08333;-2.304867e-003;3.61266;3
 69.01800; 72.50333;-7.018658e-003;3.61189;3
 69.85400; 72.92333;-1.238423e-002;3.61111;3
 70.69600; 73.34333;-1.767444e-002;3.61031;3
 71.53700; 73.76333;-2.319840e-002;3.60949;3
 72.37600; 74.18333;-2.920972e-002;3.60866;3
 73.21400; 74.60333;-3.600606e-002;3.60782;3
 74.05700; 75.02333;-4.229843e-002;3.60695;3
 74.89900; 75.44333;-4.967402e-002;3.60607;3
 75.73400; 75.86333;-5.746202e-002;3.60519;3
 76.57700; 76.28333;-6.508789e-002;3.60428;3
 77.41700; 76.70333;-7.369967e-002;3.60336;3
 78.25900; 77.12333;-8.221672e-002;3.60242;3
 79.09600; 77.54333;-9.179826e-002;3.60147;3
 79.93700; 77.96333;      -0.10124;3.60051;3
 80.77600; 78.38333;      -0.11105;3.59953;3
 81.61800; 78.80333;      -0.12135;3.59854;3
 82.45700; 79.22333;      -0.13215;3.59753;3
 83.29600; 79.64333;      -0.14324;3.59651;3
 84.13800; 80.06333;      -0.15415;3.59547;3
 84.98000; 80.48333;      -0.16492;3.59442;3
 85.81800; 80.90333;      -0.17674;3.59335;3
 86.65500; 81.32333;      -0.18819;3.59228;3
 87.49500; 81.74333;      -0.19919;3.59119;3
 88.33700; 82.16333;      -0.20945;3.59008;3
 89.17700; 82.58333;      -0.21987;3.58896;3
 90.01500; 83.00333;      -0.22941;3.58782;3
 90.85700; 83.42333;      -0.23754;3.58667;3
 91.69600; 83.84333;      -0.24545;3.58551;3
 92.53600; 84.26333;      -0.25228;3.58434;3
 93.37500; 84.68333;      -0.25749;3.58315;3
 94.21800; 85.10333;      -0.26100;3.58194;3
 95.05700; 85.52333;      -0.26362;3.58073;3
 95.89700; 85.94333;      -0.26461;3.57950;3
 96.73400; 86.36333;      -0.26412;3.57826;3
 97.57700; 86.78333;      -0.26220;3.57700;3
 98.41700; 87.20333;      -0.25926;3.57573;3
 99.25700; 87.62333;      -0.25494;3.57444;3
100.09700; 88.04333;      -0.24914;3.57315;3
100.93700; 88.46333;      -0.24276;3.57184;3
101.77500; 88.88333;      -0.23597;3.57052;3
102.61600; 89.30333;      -0.22833;3.56918;3
103.45700; 89.72333;      -0.22058;3.56783;3
104.29600; 90.14333;      -0.21256;3.56647;3
105.13600; 90.56333;      -0.20437;3.56510;3
105.97700; 90.98333;      -0.19568;3.56371;3
106.81600; 91.40333;      -0.18829;3.56231;3
107.65500; 91.82333;      -0.18051;3.56090;3
108.49500; 92.24333;      -0.17287;3.55948;3
109.33500; 92.66333;      -0.16557;3.55804;3
110.17600; 93.08333;      -0.15856;3.55659;3
111.01700; 93.50333;      -0.15156;3.55513;3
111.85600; 93.92333;      -0.14524;3.55366;3
112.69700; 94.34333;      -0.13892;3.55217;3
113.53700; 94.76333;      -0.13311;3.55067;3
114.37500; 95.18333;      -0.12722;3.54917;3
115.21600; 95.60333;      -0.12097;3.54765;3
116.05600; 96.02333;      -0.11542;3.54611;3
116.89700; 96.44333;      -0.10999;3.54457;3
117.73800; 96.86333;      -0.10401;3.54301;3
118.57600; 97.28333;-9.876038e-002;3.54144;3
119.41800; 97.70333;-9.334226e-002;3.53986;3
120.25500; 98.12333;-8.766168e-002;3.53827;3
121.09800; 98.54333;-8.221172e-002;3.53666;3
121.93500; 98.96333;-7.718472e-002;3.53505;3
122.77800; 99.38333;-7.125316e-002;3.53342;3
123.61400; 99.80333;-6.674586e-002;3.53179;3
124.46000;100.22333;-6.035384e-002;3.53013;3
125.29600;100.64333;-5.571378e-002;3.52848;3
126.13700;101.06333;-5.047188e-002;3.52680;3
126.97600;101.48333;-4.560862e-002;3.52512;3
127.81700;101.90333;-4.049252e-002;3.52343;3
128.65601;102.32333;-3.562005e-002;3.52173;3
129.49699;102.74333;-3.086692e-002;3.52001;3
130.34000;103.16333;-2.552170e-002;3.51828;3
131.17500;103.58333;-2.211578e-002;3.51655;3
132.01300;104.00333;-1.797137e-002;3.51481;3
132.85699;104.42333;-1.275891e-002;3.51304;3
133.69400;104.84333;-9.556498e-003;3.51128;3
134.53999;105.26333;-5.398664e-003;3.50949;3
135.37601;105.68333;-1.996868e-003;3.50771;3
136.21600;106.10333; 1.646924e-003;3.50591;3
137.05901;106.52333; 5.442293e-003;3.50409;3
137.89700;106.94333; 8.469428e-003;3.50228;3
138.73599;107.36333; 1.159069e-002;3.50045;3
139.57600;107.78333; 1.463589e-002;3.49861;3
140.41600;108.20333; 1.750252e-002;3.49676;3
141.25900;108.62333; 2.067966e-002;3.49489;3
142.09399;109.04333; 2.256225e-002;3.49303;3
142.93600;109.46333; 2.524467e-002;3.49115;3
143.77699;109.88333; 2.788437e-002;3.48926;3
144.61501;110.30333; 2.958083e-002;3.48736;3
145.45799;110.72333; 3.245425e-002;3.48545;3
146.29300;111.14333; 3.358443e-002;3.48354;3
147.13800;111.56333; 3.634958e-002;3.48160;3
147.97600;111.98333; 3.782640e-002;3.47967;3
148.81500;112.40333; 3.953365e-002;3.47772;3
149.65500;112.82333; 4.143742e-002;3.47577;3
150.49699;113.24333; 4.311500e-002;3.47380;3
151.33600;113.66333; 4.431340e-002;3.47183;3
152.17599;114.08333; 4.616621e-002;3.46985;3
153.01700;114.50333; 4.741412e-002;3.46785;3
153.85500;114.92333; 4.807838e-002;3.46586;3
154.69501;115.34333; 4.992546e-002;3.46385;3
155.53600;115.76333; 5.091408e-002;3.46183;3
156.37700;116.18333; 5.209925e-002;3.45980;3
157.21500;116.60333; 5.286023e-002;3.45777;3
158.05800;117.02333; 5.439350e-002;3.45571;3
158.89500;117.44333; 5.500725e-002;3.45367;3
159.73599;117.86333; 5.623272e-002;3.45160;3
160.57800;118.28333; 5.713742e-002;3.44953;3
161.41800;118.70333; 5.789316e-002;3.44745;3
162.25700;119.12333; 5.886891e-002;3.44537;3
163.09500;119.54333; 5.946498e-002;3.44328;3
163.93600;119.96333; 6.024720e-002;3.44117;3
164.77600;120.38333; 6.099567e-002;3.43906;3
165.61900;120.80333; 6.186136e-002;3.43694;3
166.45900;121.22333; 6.228812e-002;3.43481;3
167.29601;121.64333; 6.242561e-002;3.43269;3
168.13699;122.06333; 6.351396e-002;3.43054;3
168.97400;122.48333; 6.375698e-002;3.42840;3
169.81700;122.90333; 6.447704e-002;3.42623;3
170.65500;123.32333; 6.467502e-002;3.42408;3
171.49600;123.74333; 6.533844e-002;3.42190;3
172.33701;124.16333; 6.616552e-002;3.41972;3
173.17599;124.58333; 6.610976e-002;3.41753;3
174.01500;125.00333; 6.626349e-002;3.41534;3
174.85600;125.42333; 6.747738e-002;3.41314;3
175.69800;125.84333; 6.767963e-002;3.41092;3
176.53600;126.26333; 6.784657e-002;3.40871;3
177.37801;126.68333; 6.843455e-002;3.40648;3
178.21600;127.10333; 6.832234e-002;3.40426;3
179.05600;127.52333; 6.886459e-002;3.40202;3
179.89600;127.94333; 6.931419e-002;3.39978;3
180.73599;128.36333; 6.934347e-002;3.39753;3
181.57600;128.78333; 6.961871e-002;3.39527;3
182.41400;129.20333; 6.948417e-002;3.39302;3
183.25700;129.62333; 7.047558e-002;3.39074;3
184.09700;130.04333; 7.052971e-002;3.38846;3
184.93401;130.46333; 6.999674e-002;3.38619;3
185.77800;130.88333; 7.115548e-002;3.38388;3
186.61700;131.30333; 7.084613e-002;3.38159;3
187.45799;131.72333; 7.123063e-002;3.37929;3
188.29601;132.14333; 7.132104e-002;3.37698;3
189.13600;132.56333; 7.154161e-002;3.37467;3
189.97800;132.98333; 7.164518e-002;3.37234;3
190.81400;133.40333; 7.146486e-002;3.37003;3
191.65700;133.82333; 7.201734e-002;3.36769;3
192.49500;134.24333; 7.209743e-002;3.36536;3
193.33701;134.66333; 7.226125e-002;3.36301;3
194.17599;135.08333; 7.196369e-002;3.36066;3
195.01700;135.50333; 7.218686e-002;3.35830;3
195.85800;135.92333; 7.255255e-002;3.35594;3
196.69600;136.34333; 7.261020e-002;3.35358;3
197.53500;136.76333; 7.211097e-002;3.35121;3
198.37801;137.18333; 7.323754e-002;3.34882;3
199.21700;137.60333; 7.292825e-002;3.34644;3
200.05499;138.02333; 7.254715e-002;3.34406;3
200.89500;138.44333; 7.285570e-002;3.34167;3
201.73801;138.86333; 7.316540e-002;3.33926;3
202.57600;139.28333; 7.303406e-002;3.33686;3
203.41901;139.70333; 7.339223e-002;3.33445;3
204.25600;140.12333; 7.303429e-002;3.33204;3
205.09500;140.54333; 7.320145e-002;3.32963;3
205.93500;140.96333; 7.314224e-002;3.32720;3
206.77600;141.38333; 7.354936e-002;3.32477;3
207.61700;141.80333; 7.325152e-002;3.32234;3
208.45599;142.22333; 7.332400e-002;3.31990;3
209.29601;142.64333; 7.344479e-002;3.31746;3
210.14000;143.06333; 7.343481e-002;3.31500;3
210.97301;143.48333; 7.278693e-002;3.31257;3
211.82001;143.90333; 7.427782e-002;3.31010;3
212.65601;144.32333; 7.317389e-002;3.30765;3
213.49800;144.74333; 7.345220e-002;3.30518;3
214.33600;145.16333; 7.373021e-002;3.30272;3
215.17700;145.58333; 7.346752e-002;3.30024;3
216.01500;146.00333; 7.320392e-002;3.29777;3
216.85400;146.42333; 7.349491e-002;3.29529;3
217.69800;146.84333; 7.398052e-002;3.29280;3
218.53400;147.26333; 7.325765e-002;3.29032;3
219.37601;147.68333; 7.329642e-002;3.28782;3
220.21700;148.10333; 7.374635e-002;3.28532;3
221.05499;148.52333; 7.361543e-002;3.28283;3
221.89700;148.94333; 7.373960e-002;3.28032;3
222.73700;149.36333; 7.385151e-002;3.27781;3
223.57401;149.78333; 7.287116e-002;3.27531;3
224.42599;150.20333; 7.536494e-002;3.27276;3
225.25301;150.62333; 7.304575e-002;3.27028;3
226.09801;151.04333; 7.401002e-002;3.26775;3
226.94200;151.46333; 7.439152e-002;3.26521;3
227.76900;151.88333; 7.269974e-002;3.26272;3
228.61900;152.30333; 7.408164e-002;3.26016;3
229.45799;152.72333; 7.362161e-002;3.25763;3
230.29601;153.14333; 7.395420e-002;3.25510;3
231.13200;153.56333; 7.304085e-002;3.25257;3
231.97600;153.98333; 7.418184e-002;3.25002;3
232.81700;154.40333; 7.365997e-002;3.24747;3
233.65601;154.82333; 7.387165e-002;3.24492;3
234.49500;155.24333; 7.326263e-002;3.24237;3
235.33900;155.66333; 7.421142e-002;3.23981;3
236.17200;156.08333; 7.307276e-002;3.23727;3
237.01401;156.50333; 7.398575e-002;3.23470;3
237.85800;156.92333; 7.415072e-002;3.23213;3
238.69299;157.34333; 7.342824e-002;3.22958;3
239.53700;157.76333; 7.404875e-002;3.22700;3
240.37801;158.18333; 7.426301e-002;3.22443;3
241.21700;158.60333; 7.384822e-002;3.22186;3
242.05701;159.02333; 7.422302e-002;3.21928;3
242.89700;159.44333; 7.407963e-002;3.21670;3
243.73801;159.86333; 7.418355e-002;3.21412;3
244.57401;160.28333; 7.324729e-002;3.21155;3
245.41701;160.70333; 7.435423e-002;3.20896;3
246.26500;161.12333; 7.493119e-002;3.20635;3
247.08900;161.54333; 7.288699e-002;3.20381;3
247.93700;161.96333; 7.400995e-002;3.20119;3
248.77699;162.38333; 7.406468e-002;3.19860;3
249.61501;162.80333; 7.389534e-002;3.19601;3
250.45700;163.22333; 7.391325e-002;3.19341;3
251.29401;163.64333; 7.359393e-002;3.19082;3
252.13499;164.06333; 7.393556e-002;3.18822;3
252.97600;164.48333; 7.329235e-002;3.18562;3
253.81500;164.90333; 7.339674e-002;3.18302;3
254.65401;165.32333; 7.326394e-002;3.18042;3
255.49500;165.74333; 7.373161e-002;3.17781;3
256.33600;166.16333; 7.369949e-002;3.17520;3
257.17499;166.58333; 7.335380e-002;3.17259;3
258.01700;167.00333; 7.332159e-002;3.16998;3
258.85599;167.42333; 7.308799e-002;3.16737;3
259.69601;167.84333; 7.311793e-002;3.16476;3
260.53699;168.26333; 7.304762e-002;3.16214;3
261.37701;168.68333; 7.303990e-002;3.15952;3
262.21399;169.10333; 7.207492e-002;3.15692;3
263.05399;169.52333; 7.196565e-002;3.15430;3
263.89700;169.94333; 7.200816e-002;3.15167;3
264.73599;170.36333; 7.129280e-002;3.14906;3
265.57599;170.78333; 7.069013e-002;3.14644;3
266.41599;171.20333; 7.073111e-002;3.14382;3
267.25601;171.62333; 6.986137e-002;3.14119;3
268.09698;172.04333; 6.969940e-002;3.13857;3
268.93399;172.46333; 6.804112e-002;3.13595;3
269.77802;172.88333; 6.814435e-002;3.13332;3
270.61401;173.30333; 6.688796e-002;3.13070;3
271.46399;173.72333; 6.821120e-002;3.12805;3
272.29599;174.14333; 6.458716e-002;3.12544;3
273.12799;174.56333; 6.155513e-002;3.12284;3
273.97699;174.98333; 6.314444e-002;3.12019;3
274.81601;175.40333; 6.121646e-002;3.11756;3
275.65601;175.82333; 5.943853e-002;3.11493;3
276.49701;176.24333; 5.770887e-002;3.11230;3
277.33499;176.66333; 5.550289e-002;3.10968;3
278.17599;177.08333; 5.390766e-002;3.10705;3
279.01599;177.50333; 5.191274e-002;3.10442;3
279.85599;177.92333; 4.946606e-002;3.10179;3
279.58600;178.08333; 5.687983e-002;3.10263;4
274.66101;178.18833;      -0.52987;3.11805;4
266.75800;178.29333;      -1.68831;3.14275;4
259.04401;178.39833;      -2.47695;3.16678;4
253.02499;178.50333;      -2.60888;3.18547;4
248.35800;178.60833;      -2.33454;3.19990;4
243.97200;178.71333;      -2.03665;3.21340;4
239.15700;178.81833;      -1.91728;3.22816;4
233.85699;178.92333;      -1.95360;3.24431;4
228.37500;179.02833;      -2.03173;3.26090;4
222.96300;179.13333;      -2.07065;3.27714;4
217.69701;179.23833;      -2.06209;3.29280;4
212.51401;179.34333;      -2.02507;3.30807;4
207.33000;179.44833;      -1.99484;3.32317;4
202.10300;179.55333;      -1.97981;3.33822;4
196.84399;179.65833;      -1.97514;3.35316;4
191.57401;179.76333;      -1.97110;3.36792;4
186.31400;179.86833;      -1.96352;3.38242;4
181.06400;179.97333;      -1.95371;3.39665;4
175.81900;180.07833;      -1.94271;3.41060;4
170.57700;180.18333;      -1.93153;3.42428;4
165.33099;180.28833;      -1.92006;3.43767;4
160.08099;180.39333;      -1.90893;3.45076;4
154.83000;180.49833;      -1.89908;3.46352;4
149.58200;180.60333;      -1.88872;3.47594;4
144.33299;180.70833;      -1.87681;3.48800;4
139.08501;180.81333;      -1.86370;3.49968;4
133.83400;180.91833;      -1.85304;3.51098;4
128.58400;181.02333;      -1.84209;3.52187;4
123.33300;181.12833;      -1.83017;3.53234;4
118.08700;181.23333;      -1.81737;3.54236;4
112.83900;181.33833;      -1.80494;3.55192;4
107.58600;181.44333;      -1.79364;3.56102;4
102.32900;181.54833;      -1.78287;3.56964;4
 97.07400;181.65333;      -1.77073;3.57775;4
 91.82200;181.75833;      -1.75767;3.58534;4
 86.57100;181.86333;      -1.74190;3.59239;4
 81.32000;181.96833;      -1.71566;3.59889;4
 76.06600;182.07333;      -1.66685;3.60483;4
 70.81500;182.17833;      -1.59353;3.61019;4
 65.56000;182.28333;      -1.50881;3.61497;4
 60.30600;182.38833;      -1.42825;3.61914;4
 55.05100;182.49333;      -1.35975;3.62269;4
 49.80000;182.59833;      -1.30376;3.62561;4
 44.55900;182.70333;      -1.25878;3.62789;4
 39.32300;182.80833;      -1.22082;3.62951;4
 34.13000;182.91333;      -1.14467;3.63047;4
 28.81400;183.01833;      -1.14404;3.63077;4
 23.51700;183.12333;      -1.13127;3.63038;4
 16.68100;183.26333;      -1.11175;3.62882;5
 18.14100;183.47333;      -0.44502;3.62925;5
 21.61900;183.68333;       0.28406;3.63006;5
 20.02500;183.89333;-7.363830e-003;3.62973;5
 19.74800;184.10333;-5.707916e-002;3.62966;5
 20.32700;184.31500; 2.722355e-002;3.62980;6
 20.99900;184.52500; 9.349271e-002;3.62994;6
 20.43600;184.73500;-3.298233e-002;3.62982;6
 22.20200;184.94500;       0.12408;3.63017;6
 21.60900;185.15500; 3.388334e-002;3.63006;6
 22.33100;185.36500; 2.311429e-002;3.63019;6
 22.96600;185.57500;       0.10084;3.63029;6
 22.93200;185.78500; 8.707290e-003;3.63029;6
 23.88500;185.99500; 9.073136e-002;3.63043;6
 23.72500;186.20500; 2.398717e-002;3.63040;6
 24.72700;186.41500; 7.231448e-002;3.63053;6
 24.70500;186.62500; 5.787430e-002;3.63053;6
 25.21000;186.83500; 2.139157e-002;3.63058;6
 25.99700;187.04500;       0.11025;3.63065;6
 25.70200;187.25500;-6.303196e-003;3.63062;6
 26.94500;187.46500;       0.10143;3.63071;6
 26.66300;187.67500; 3.213362e-002;3.63070;6
 27.51500;187.88500; 5.038570e-002;3.63074;6
 27.83700;188.09500; 8.244901e-002;3.63075;6
 28.00300;188.30500; 1.000672e-002;3.63076;6
 28.98400;188.51500;       0.10837;3.63077;6
 28.65500;188.72500; 6.312264e-003;3.63077;6
 29.83100;188.93500; 8.691092e-002;3.63077;6
 29.69100;189.14500; 5.016430e-002;3.63077;6
 30.32200;189.35500; 3.231627e-002;3.63076;6
 30.92800;189.56500;       0.10064;3.63074;6
 30.82300;189.77500; 6.072298e-004;3.63074;6
 31.97200;189.98500;       0.10727;3.63068;6
 31.63800;190.19500; 2.017947e-002;3.63070;6
 32.65600;190.40500; 6.752227e-002;3.63063;6
 32.77500;190.61500; 7.181722e-002;3.63062;6
 33.11800;190.82500; 1.643554e-002;3.63058;6
 33.97900;191.03500;       0.11006;3.63049;6
 33.69900;191.24500; 1.272696e-003;3.63052;6
 34.90100;191.45500; 9.835521e-002;3.63037;6
 34.65800;191.66500; 3.806011e-002;3.63040;6
 35.45900;191.87500; 4.677504e-002;3.63029;6
 35.86900;192.08500; 9.168360e-002;3.63022;6
 35.92800;192.29500; 4.955291e-003;3.63021;6
 36.99300;192.50500;       0.11300;3.63002;6
 36.64100;192.71500; 1.021131e-002;3.63009;6
 37.77000;192.92500; 8.227350e-002;3.62987;6
 37.72500;193.13500; 5.937937e-002;3.62988;6
 38.25000;193.34500; 2.744710e-002;3.62976;6
 38.94700;193.55500;       0.10659;3.62960;6
 38.78100;193.76500; 5.827610e-004;3.62964;6
 39.95400;193.97500;       0.10776;3.62935;6
 39.63800;194.18500; 2.586075e-002;3.62943;6
 40.59600;194.39500; 6.251796e-002;3.62918;6
 40.81100;194.60500; 8.101836e-002;3.62912;6
 41.04600;194.81500; 1.171683e-002;3.62905;6
 41.99600;195.02500;       0.11525;3.62876;6
 41.67700;195.23500; 3.758793e-003;3.62886;6
 42.85800;195.44500; 9.542296e-002;3.62849;6
 42.68100;195.65500; 4.607982e-002;3.62855;6
 43.38900;195.86500; 4.123082e-002;3.62831;6
 43.90100;196.07500; 9.955104e-002;3.62813;6
 43.87100;196.28500; 2.598757e-003;3.62814;6
 44.99000;196.49500;       0.11501;3.62772;6
 44.63300;196.70500; 1.461165e-002;3.62786;6
 45.71200;196.91500; 7.782060e-002;3.62744;6
 45.75500;197.12500; 6.815668e-002;3.62742;6
 46.18100;197.33500; 2.255230e-002;3.62725;6
 46.96700;197.54500;       0.11241;3.62692;6
 46.73900;197.75500; 5.256438e-004;3.62702;6
 47.92900;197.96500;       0.10733;3.62650;6
 47.64300;198.17500; 3.196553e-002;3.62663;6
 48.52700;198.38500; 5.725887e-002;3.62622;6
 48.84600;198.59500; 8.955258e-002;3.62607;6
 48.97900;198.80500; 7.589376e-003;3.62601;6
 49.99700;199.01500;       0.11845;3.62551;6
 49.66000;199.22500; 6.743727e-003;3.62568;6
 50.81200;199.43500; 9.208763e-002;3.62510;6
 50.70300;199.64500; 5.393310e-002;3.62515;6
 51.31900;199.85500; 3.588178e-002;3.62483;6
 51.92500;200.06500;       0.10688;3.62451;6
 51.82000;200.27500; 6.020906e-004;3.62456;6
 52.97500;200.48500;       0.11614;3.62392;6
 52.63200;200.69500; 2.012285e-002;3.62412;6
 53.65400;200.90500; 7.275627e-002;3.62353;6
 53.78400;201.11500; 7.662671e-002;3.62345;6
 54.11200;201.32500; 1.742763e-002;3.62326;6
 54.98300;201.53500;       0.11790;3.62273;6
 54.70500;201.74500; 1.577489e-003;3.62290;6
 55.89700;201.95500;       0.10566;3.62216;6
 55.66000;202.16500; 3.963298e-002;3.62231;6
 56.45300;202.37500; 5.070639e-002;3.62180;6
 56.87300;202.58500; 9.766845e-002;3.62153;6
 56.92400;202.79500; 4.840370e-003;3.62150;6
 57.99700;203.00500;       0.12134;3.62078;6
 57.64500;203.21500; 1.037478e-002;3.62101;6
 58.76500;203.42500; 8.854080e-002;3.62024;6
 58.72800;203.63500; 6.255120e-002;3.62027;6
 59.25000;203.84500; 3.033739e-002;3.61990;6
 59.95000;204.05500;       0.11364;3.61940;6
 59.77500;204.26500;-3.334380e-004;3.61953;6
 60.95600;204.47500;       0.11635;3.61866;6
 60.63700;204.68500; 2.613993e-002;3.61889;6
 61.59000;204.89500; 6.755390e-002;3.61818;6
 61.81800;205.10500; 8.572135e-002;3.61800;6
 62.04600;205.31500; 1.308769e-002;3.61783;6
 62.99100;205.52500;       0.12264;3.61708;6
 62.67700;205.73500; 3.479501e-003;3.61733;6
 63.85900;205.94500;       0.10359;3.61639;6
 63.68200;206.15500; 4.782191e-002;3.61653;6
 64.38600;206.36500; 4.539819e-002;3.61595;6
 64.90200;206.57500;       0.10586;3.61552;6
 64.87100;206.78500; 2.470174e-003;3.61555;6
 65.98900;206.99500;       0.12388;3.61460;6
 65.63600;207.20500; 1.481319e-002;3.61490;6
 66.71000;207.41500; 8.483029e-002;3.61398;6
 66.75600;207.62500; 7.185888e-002;3.61393;6
 67.17600;207.83500; 2.503985e-002;3.61356;6
 67.97000;208.04500;       0.12110;3.61285;6
 67.73800;208.25500; 4.447358e-004;3.61306;6
 68.92700;208.46500;       0.11605;3.61198;6
 68.65000;208.67500; 3.397043e-002;3.61223;6
 69.52400;208.88500; 6.287748e-002;3.61142;6
 69.84400;209.09500; 9.519855e-002;3.61112;6
 69.98100;209.30500; 9.816572e-003;3.61099;6
 71.00000;209.51500;       0.12880;3.61002;6
 70.65500;209.72500; 6.667179e-003;3.61035;6
 71.81200;209.93500;       0.10181;3.60922;6
 71.70200;210.14500; 5.783127e-002;3.60933;6
 72.31500;210.35500; 4.102371e-002;3.60872;6
 72.92700;210.56500;       0.11551;3.60811;6
 72.82100;210.77500; 2.108008e-003;3.60821;6
 73.97600;210.98500;       0.12768;3.60704;6
 73.63500;211.19500; 2.196324e-002;3.60739;6
 74.65200;211.40500; 8.237186e-002;3.60633;6
 74.78600;211.61500; 8.363287e-002;3.60619;6
 75.10900;211.82500; 2.225568e-002;3.60585;6
 75.98300;212.03500;       0.13029;3.60492;6
 75.70300;212.24500; 3.210630e-003;3.60522;6
 76.89800;212.45500;       0.11919;3.60393;6
 76.66400;212.66500; 4.443718e-002;3.60418;6
 77.45500;212.87500; 6.076365e-002;3.60332;6
 77.87300;213.08500;       0.10882;3.60285;6
 77.92300;213.29500; 9.613718e-003;3.60280;6
 78.99700;213.50500;       0.13834;3.60159;6
 78.64300;213.71500; 1.404288e-002;3.60199;6
 79.76600;213.92500;       0.10455;3.60071;6
 79.73100;214.13500; 7.203495e-002;3.60075;6
 80.24900;214.34500; 4.010079e-002;3.60015;6
 80.95200;214.55500;       0.13091;3.59932;6
 80.77500;214.76500; 4.847927e-003;3.59953;6
 81.95700;214.97500;       0.13691;3.59813;6
 81.64000;215.18500; 3.370498e-002;3.59851;6
 82.58700;215.39500; 8.352158e-002;3.59737;6
 82.81600;215.60500;       0.10128;3.59709;6
 83.04600;215.81500; 2.203044e-002;3.59681;6
 83.99300;216.02500;       0.14593;3.59565;6
 83.67600;216.23500; 8.555897e-003;3.59604;6
 84.86000;216.44500;       0.12644;3.59457;6
 84.68300;216.65500; 5.925002e-002;3.59479;6
 85.38700;216.86500; 5.984507e-002;3.59390;6
 85.90500;217.07500;       0.12746;3.59324;6
 85.86800;217.28500; 9.126215e-003;3.59329;6
 86.99000;217.49500;       0.15029;3.59184;6
 86.63600;217.70500; 2.152799e-002;3.59230;6
 87.71000;217.91500;       0.10671;3.59090;6
 87.75600;218.12500; 8.692371e-002;3.59084;6
 88.17600;218.33500; 3.622049e-002;3.59029;6
 88.96700;218.54500;       0.14551;3.58924;6
 88.73800;218.75500; 4.859360e-003;3.58954;6
 89.92900;218.96500;       0.14294;3.58794;6
 89.65000;219.17500; 4.165687e-002;3.58832;6
 90.52600;219.38500; 8.125219e-002;3.58713;6
 90.84700;219.59500;       0.11389;3.58669;6
 90.98300;219.80500; 1.650436e-002;3.58650;6
 91.99900;220.01500;       0.15486;3.58509;6
 91.65500;220.22500; 9.844476e-003;3.58557;6
 92.81000;220.43500;       0.12424;3.58395;6
 92.70700;220.64500; 6.850168e-002;3.58409;6
 93.31800;220.85500; 5.340874e-002;3.58323;6
 93.92700;221.06500;       0.13633;3.58236;6
 93.81700;221.27500; 5.034346e-003;3.58252;6
 94.97800;221.48500;       0.15328;3.58084;6
 94.63500;221.69500; 2.542496e-002;3.58134;6
 95.64900;221.90500;       0.10063;3.57986;6
 95.78600;222.11500; 9.615862e-002;3.57966;6
 96.10900;222.32500; 2.916650e-002;3.57918;6
 96.98200;222.53500;       0.15121;3.57789;6
 96.70500;222.74500; 3.829044e-003;3.57830;6
 97.89900;222.95500;       0.14058;3.57651;6
 97.66200;223.16500; 4.841614e-002;3.57687;6
 98.45500;223.37500; 7.277282e-002;3.57567;6
 98.87500;223.58500;       0.12261;3.57503;6
 98.92500;223.79500; 1.151748e-002;3.57495;6
 99.99500;224.00500;       0.15635;3.57330;6
 99.64300;224.21500; 1.289156e-002;3.57385;6
100.76400;224.42500;       0.11962;3.57211;6
100.72900;224.63500; 7.672260e-002;3.57216;6
101.25000;224.84500; 4.570377e-002;3.57135;6
101.94900;225.05500;       0.14321;3.57024;6
101.77800;225.26500; 3.323678e-003;3.57051;6
102.95800;225.47500;       0.15154;3.56863;6
102.63600;225.68500; 3.085938e-002;3.56915;6
103.58900;225.89500; 9.342088e-002;3.56762;6
103.81400;226.10500;       0.10515;3.56726;6
104.04400;226.31500; 2.227648e-002;3.56688;6
104.99300;226.52500;       0.15558;3.56533;6
104.68100;226.73500; 5.346621e-003;3.56584;6
105.85900;226.94500;       0.13641;3.56391;6
105.67900;227.15500; 5.677667e-002;3.56420;6
106.39100;227.36500; 6.480753e-002;3.56302;6
106.90100;227.57500;       0.13046;3.56217;6
106.87100;227.78500; 7.281643e-003;3.56222;6
107.98700;227.99500;       0.15757;3.56034;6
107.63700;228.20500; 1.720371e-002;3.56093;6
108.71400;228.41500;       0.11323;3.55911;6
108.75300;228.62500; 8.545099e-002;3.55904;6
109.17900;228.83500; 3.795911e-002;3.55831;6
109.97000;229.04500;       0.14990;3.55695;6
109.73400;229.25500; 1.534238e-003;3.55736;6
110.92600;229.46500;       0.14894;3.55529;6
110.65000;229.67500; 3.903827e-002;3.55577;6
111.52600;229.88500; 8.535044e-002;3.55424;6
111.84200;230.09500;       0.11371;3.55368;6
111.98600;230.30500; 1.694358e-002;3.55343;6
112.99800;230.51500;       0.15885;3.55164;6
112.65500;230.72500; 6.832101e-003;3.55225;6
113.82000;230.93500;       0.13154;3.55017;6
113.70000;231.14500; 6.552033e-002;3.55038;6
114.31600;231.35500; 5.579433e-002;3.54928;6
114.92700;231.56500;       0.13839;3.54817;6
114.82300;231.77500; 4.394570e-003;3.54836;6
115.97500;231.98500;       0.15710;3.54626;6
115.63500;232.19500; 2.286570e-002;3.54688;6
116.65400;232.40500;       0.10583;3.54501;6
116.78400;232.61500; 9.522729e-002;3.54477;6
117.11100;232.82500; 3.008850e-002;3.54417;6
117.98300;233.03500;       0.15492;3.54255;6
117.70600;233.24500; 1.898374e-003;3.54307;6
118.89600;233.45500;       0.14581;3.54084;6
118.65900;233.66500; 4.605848e-002;3.54129;6
119.45800;233.87500; 7.666954e-002;3.53978;6
119.87000;234.08500;       0.12315;3.53900;6
119.92500;234.29500; 1.126983e-002;3.53890;6
120.99700;234.50500;       0.16084;3.53685;6
120.64200;234.71500; 9.939922e-003;3.53753;6
121.76900;234.92500;       0.12585;3.53537;6
121.72600;235.13500; 7.304053e-002;3.53546;6
122.25000;235.34500; 4.690600e-002;3.53444;6
122.94900;235.55500;       0.14540;3.53309;6
122.77800;235.76500; 1.676750e-003;3.53342;6
123.95400;235.97500;       0.15608;3.53112;6
123.63800;236.18500; 2.800817e-002;3.53174;6
124.59500;236.39500; 9.795834e-002;3.52986;6
124.80800;236.60500;       0.10478;3.52944;6
125.04700;236.81500; 2.307369e-002;3.52897;6
125.99400;237.02500;       0.16014;3.52709;6
125.67800;237.23500; 2.040820e-003;3.52772;6
126.85800;237.44500;       0.14182;3.52536;6
126.67900;237.65500; 5.460767e-002;3.52572;6
127.39100;237.86500; 6.762181e-002;3.52429;6
127.89900;238.07500;       0.13160;3.52326;6
127.87400;238.28500; 6.330180e-003;3.52331;6
128.98900;238.49500;       0.16279;3.52105;6
128.63499;238.70500; 1.264953e-002;3.52177;6
129.71001;238.91500;       0.11819;3.51957;6
129.75200;239.12500; 8.532220e-002;3.51949;6
130.17999;239.33500; 3.616832e-002;3.51861;6
130.96400;239.54500;       0.15237;3.51699;6
130.73500;239.75500;-2.959857e-004;3.51746;6
131.93401;239.96500;       0.15644;3.51497;6
131.64301;240.17500; 3.387176e-002;3.51558;6
132.52901;240.38500; 8.889423e-002;3.51373;6
132.84300;240.59500;       0.11459;3.51307;6
132.98700;240.80500; 1.712290e-002;3.51277;6
133.99400;241.01500;       0.16239;3.51065;6
133.65900;241.22500; 4.936880e-003;3.51135;6
134.81500;241.43500;       0.13593;3.50890;6
134.69701;241.64500; 6.360112e-002;3.50915;6
135.32100;241.85500; 5.911016e-002;3.50782;6
135.92300;242.06500;       0.13973;3.50654;6
135.82100;242.27500; 2.525177e-003;3.50676;6
136.97701;242.48500;       0.16261;3.50427;6
136.63400;242.69500; 1.999250e-002;3.50501;6
137.65601;242.90500;       0.11019;3.50280;6
137.78000;243.11500; 9.439587e-002;3.50253;6
138.11501;243.32500; 3.162761e-002;3.50180;6
138.98100;243.53500;       0.15746;3.49991;6
138.69901;243.74500;-1.730168e-003;3.50053;6
139.90100;243.95500;       0.15181;3.49789;6
139.66100;244.16500; 4.374410e-002;3.49842;6
140.45700;244.37500; 7.928977e-002;3.49667;6
140.87000;244.58500;       0.12341;3.49575;6
140.93201;244.79500; 1.201844e-002;3.49562;6
141.99400;245.00500;       0.16469;3.49326;6
141.64200;245.21500; 7.248247e-003;3.49404;6
142.76900;245.42500;       0.12983;3.49152;6
142.72099;245.63500; 7.276816e-002;3.49163;6
143.25000;245.84500; 4.959758e-002;3.49044;6
143.94800;246.05500;       0.14789;3.48887;6
143.77699;246.26500;-2.787731e-004;3.48926;6
144.95200;246.47500;       0.16073;3.48660;6
144.63901;246.68500; 2.690119e-002;3.48731;6
145.59300;246.89500;       0.10160;3.48514;6
145.80800;247.10500;       0.10414;3.48465;6
146.05200;247.31500; 2.403883e-002;3.48409;6
146.99100;247.52500;       0.16232;3.48194;6
146.67400;247.73500;-2.560821e-004;3.48267;6
147.86200;247.94500;       0.14637;3.47993;6
147.67799;248.15500; 5.232269e-002;3.48036;6
148.39200;248.36500; 7.062608e-002;3.47871;6
148.89700;248.57500;       0.13247;3.47753;6
148.87300;248.78500; 5.847379e-003;3.47759;6
149.98801;248.99500;       0.16656;3.47499;6
149.63600;249.20500; 1.157628e-002;3.47581;6
150.71400;249.41500;       0.12215;3.47329;6
150.75000;249.62500; 8.326153e-002;3.47321;6
151.18300;249.83500; 4.075515e-002;3.47219;6
151.96400;250.04500;       0.15449;3.47035;6
151.73900;250.25500;-2.149219e-003;3.47088;6
152.93300;250.46500;       0.15939;3.46805;6
152.64700;250.67500; 3.353398e-002;3.46873;6
153.52800;250.88500; 9.204284e-002;3.46664;6
153.83800;251.09500;       0.11398;3.46590;6
153.98801;251.30500; 1.693780e-002;3.46554;6
154.99600;251.51500;       0.16644;3.46312;6
154.65401;251.72500; 7.408012e-004;3.46394;6
155.82100;251.93500;       0.14117;3.46114;6
155.69800;252.14500; 6.163721e-002;3.46144;6
156.32300;252.35500; 6.060010e-002;3.45993;6
156.91901;252.56500;       0.14099;3.45848;6
156.82300;252.77500; 1.658145e-003;3.45872;6
157.97600;252.98500;       0.16696;3.45591;6
157.63000;253.19500; 1.651722e-002;3.45676;6
158.65900;253.40500;       0.11417;3.45425;6
158.78000;253.61500; 9.352047e-002;3.45395;6
159.11301;253.82500; 3.161860e-002;3.45313;6
159.97900;254.03500;       0.16033;3.45101;6
159.70599;254.24500;-2.496897e-003;3.45168;6
160.89600;254.45500;       0.15503;3.44874;6
160.65601;254.66500; 4.106562e-002;3.44934;6
161.46400;254.87500; 8.313820e-002;3.44734;6
161.87100;255.08500;       0.12439;3.44633;6
161.92700;255.29500; 9.543329e-003;3.44619;6
162.99400;255.50500;       0.16859;3.44353;6
162.64301;255.71500; 4.623540e-003;3.44441;6
163.76900;255.92500;       0.13363;3.44159;6
163.72301;256.13500; 7.168257e-002;3.44171;6
164.25400;256.34500; 5.151512e-002;3.44038;6
164.94701;256.55500;       0.14958;3.43863;6
164.77901;256.76500;-2.345963e-003;3.43906;6
165.95300;256.97500;       0.16502;3.43609;6
165.63499;257.18500; 2.319608e-002;3.43690;6
166.59399;257.39500;       0.10496;3.43447;6
166.80800;257.60500;       0.10366;3.43393;6
167.05000;257.81500; 2.362439e-002;3.43331;6
167.99001;258.02500;       0.16556;3.43092;6
167.67999;258.23500;-2.570198e-003;3.43171;6
168.86099;258.44500;       0.15049;3.42869;6
168.67500;258.65500; 4.996913e-002;3.42917;6
169.39500;258.86500; 7.308157e-002;3.42732;6
169.89301;259.07500;       0.13286;3.42604;6
169.87399;259.28500; 4.514088e-003;3.42609;6
170.99001;259.49500;       0.17056;3.42321;6
170.63499;259.70500; 8.088526e-003;3.42413;6
171.71400;259.91500;       0.12589;3.42134;6
171.74800;260.12500; 8.165140e-002;3.42125;6
172.18600;260.33500; 4.181172e-002;3.42011;6
172.96500;260.54500;       0.15669;3.41808;6
172.74001;260.75500;-4.222828e-003;3.41867;6
173.92799;260.96500;       0.16228;3.41557;6
173.64101;261.17500; 2.969123e-002;3.41632;6
174.53200;261.38500; 9.545688e-002;3.41399;6
174.83800;261.59500;       0.11406;3.41318;6
174.98900;261.80500; 1.606424e-002;3.41279;6
175.99200;262.01500;       0.16894;3.41015;6
175.65700;262.22500;-1.292752e-003;3.41103;6
176.82001;262.43500;       0.14500;3.40796;6
176.69400;262.64500; 5.910614e-002;3.40830;6
177.32201;262.85500; 6.217173e-002;3.40663;6
177.92400;263.06500;       0.14250;3.40504;6
177.82700;263.27500;-4.107661e-004;3.40529;6
178.97099;263.48500;       0.16927;3.40225;6
178.63100;263.69500; 1.348975e-002;3.40316;6
179.66000;263.90500;       0.11781;3.40041;6
179.77901;264.11500; 9.198055e-002;3.40009;6
180.11501;264.32500; 3.199778e-002;3.39919;6
180.97900;264.53500;       0.16269;3.39688;6
180.70799;264.74500;-5.303628e-003;3.39761;6
181.89500;264.95500;       0.15820;3.39441;6
181.65800;265.16500; 3.840409e-002;3.39505;6
182.46700;265.37500; 8.561370e-002;3.39287;6
182.86400;265.58500;       0.12314;3.39180;6
182.92999;265.79500; 9.070143e-003;3.39162;6
183.99899;266.00500;       0.17294;3.38873;6
183.64000;266.21500; 3.998099e-004;3.38970;6
184.76801;266.42500;       0.13737;3.38664;6
184.72200;266.63500; 6.931970e-002;3.38676;6
185.25400;266.84500; 5.212382e-002;3.38531;6
185.94000;267.05500;       0.14965;3.38344;6
185.77699;267.26500;-4.246694e-003;3.38389;6
186.95900;267.47500;       0.16947;3.38066;6
186.63499;267.68500; 1.962073e-002;3.38154;6
187.59599;267.89500;       0.10763;3.37891;6
187.80800;268.10500;       0.10293;3.37833;6
188.05099;268.31500; 2.326655e-002;3.37766;6
188.98801;268.52500;       0.16713;3.37508;6
188.68100;268.73500;-5.067927e-003;3.37592;6
189.86099;268.94500;       0.15373;3.37267;6
189.67300;269.15500; 4.675144e-002;3.37319;6
190.39900;269.36500; 7.510561e-002;3.37118;6
190.89400;269.57500;       0.13298;3.36981;6
190.87100;269.78500; 2.164927e-003;3.36987;6
191.98900;269.99500;       0.17411;3.36677;6
191.63300;270.20500; 4.877411e-003;3.36776;6
192.71400;270.41500;       0.12907;3.36475;6
192.74600;270.62500; 7.952288e-002;3.36466;6
193.18800;270.83500; 4.261695e-002;3.36342;6
193.96201;271.04500;       0.15724;3.36126;6
193.73801;271.25500;-7.339442e-003;3.36189;6
194.93100;271.46500;       0.16629;3.35854;6
194.64700;271.67500; 2.717283e-002;3.35934;6
195.53200;271.88500; 9.765412e-002;3.35686;6
195.83299;272.09500;       0.11233;3.35601;6
195.98801;272.30500; 1.530153e-002;3.35557;6
196.99600;272.51500;       0.17189;3.35273;6
196.65800;272.72500;-4.592369e-003;3.35368;6
197.81900;272.93500;       0.14747;3.35041;6
197.69099;273.14500; 5.611798e-002;3.35077;6
198.32600;273.35500; 6.353279e-002;3.34897;6
198.92200;273.56500;       0.14314;3.34728;6
198.82401;273.77500;-2.728063e-003;3.34756;6
199.97501;273.98500;       0.17314;3.34429;6
199.63200;274.19500; 1.033096e-002;3.34526;6
200.65601;274.40500;       0.11960;3.34235;6
200.77699;274.61500; 9.074329e-002;3.34200;6
201.12000;274.82500; 3.207361e-002;3.34103;6
201.97600;275.03500;       0.16342;3.33858;6
201.70700;275.24500;-8.438126e-003;3.33935;6
202.89799;275.45500;       0.16173;3.33594;6
202.65601;275.66500; 3.536602e-002;3.33663;6
203.46500;275.87500; 8.702678e-002;3.33431;6
203.86501;276.08500;       0.12339;3.33317;6
203.93100;276.29500; 7.256072e-003;3.33298;6
204.99600;276.50500;       0.17446;3.32991;6
204.63800;276.71500;-2.941148e-003;3.33094;6
205.76601;276.92500;       0.13944;3.32769;6
205.72501;277.13500; 6.780755e-002;3.32781;6
206.25600;277.34500; 5.238591e-002;3.32628;6
206.94200;277.55500;       0.15035;3.32429;6
206.78101;277.76500;-6.743101e-003;3.32476;6
207.95900;277.97500;       0.17200;3.32135;6
207.62900;278.18500; 1.562094e-002;3.32230;6
208.59700;278.39500;       0.11009;3.31949;6
208.80901;278.60500;       0.10177;3.31888;6
209.04900;278.81500; 2.195254e-002;3.31818;6
209.98700;279.02500;       0.16885;3.31545;6
209.68300;279.23500;-8.137782e-003;3.31633;6
210.86200;279.44500;       0.15642;3.31290;6
210.67200;279.65500; 4.412193e-002;3.31345;6
211.39700;279.86500; 7.548414e-002;3.31133;6
211.89500;280.07500;       0.13356;3.30988;6
211.87300;280.28500; 2.406848e-004;3.30994;6
212.98801;280.49500;       0.17543;3.30668;6
212.63499;280.70500; 1.498951e-003;3.30771;6
213.71600;280.91500;       0.13118;3.30454;6
213.74600;281.12500; 7.735800e-002;3.30445;6
214.19099;281.33500; 4.265489e-002;3.30314;6
214.95799;281.54500;       0.15769;3.30089;6
214.73900;281.75500;-1.020103e-002;3.30153;6
215.93300;281.96500;       0.16954;3.29801;6
215.64101;282.17500; 2.309778e-002;3.29887;6
216.53500;282.38500; 9.920177e-002;3.29624;6
216.83200;282.59500;       0.11129;3.29536;6
216.99300;282.80500; 1.400968e-002;3.29488;6
217.99300;283.01500;       0.17308;3.29192;6
217.65700;283.22500;-8.474247e-003;3.29292;6
218.81900;283.43500;       0.15016;3.28948;6
218.69299;283.64500; 5.382938e-002;3.28985;6
219.32899;283.85500; 6.447578e-002;3.28796;6
219.91200;284.06500;       0.14117;3.28623;6
219.82899;284.27500;-4.453579e-003;3.28648;6
220.97501;284.48500;       0.17496;3.28307;6
220.62500;284.69500; 4.924308e-003;3.28411;6
221.66499;284.90500;       0.12263;3.28101;6
221.77400;285.11500; 8.850843e-002;3.28069;6
222.11900;285.32500; 3.071653e-002;3.27966;6
222.97800;285.53500;       0.16539;3.27709;6
222.70700;285.74500;-1.227737e-002;3.27790;6
223.89700;285.95500;       0.16402;3.27435;6
223.65601;286.16500; 3.168021e-002;3.27507;6
224.46400;286.37500; 8.739688e-002;3.27265;6
224.86301;286.58500;       0.12223;3.27145;6
224.93401;286.79500; 5.856135e-003;3.27124;6
225.99200;287.00500;       0.17539;3.26807;6
225.64301;287.21500;-6.346454e-003;3.26911;6
226.77100;287.42500;       0.14216;3.26573;6
226.71600;287.63500; 6.392686e-002;3.26589;6
227.25800;287.84500; 5.254718e-002;3.26426;6
227.94099;288.05500;       0.15084;3.26221;6
227.78300;288.26500;-1.025243e-002;3.26268;6
228.95599;288.47500;       0.17354;3.25915;6
228.62801;288.68500; 1.110864e-002;3.26014;6
229.59801;288.89500;       0.11105;3.25721;6
229.80499;289.10500; 9.963580e-002;3.25658;6
230.05499;289.31500; 2.084155e-002;3.25583;6
230.98500;289.52500;       0.16965;3.25302;6
230.67999;289.73500;-1.284539e-002;3.25394;6
231.86200;289.94500;       0.15860;3.25036;6
231.66901;290.15500; 4.012257e-002;3.25095;6
232.39900;290.36500; 7.552546e-002;3.24873;6
232.89301;290.57500;       0.13227;3.24724;6
232.87199;290.78500;-4.437085e-003;3.24730;6
233.99400;290.99500;       0.17849;3.24389;6
233.63499;291.20500;-3.133506e-003;3.24499;6
234.71001;291.41500;       0.13147;3.24172;6
234.74699;291.62500; 7.498994e-002;3.24161;6
235.19299;291.83500; 4.156347e-002;3.24025;6
235.95399;292.04500;       0.15656;3.23793;6
235.74600;292.25500;-1.314215e-002;3.23857;6
236.93300;292.46500;       0.17027;3.23495;6
236.63100;292.67500; 1.712800e-002;3.23587;6
237.53799;292.88500;       0.10028;3.23311;6
237.83400;293.09500;       0.11004;3.23220;6
237.99100;293.30500; 1.039056e-002;3.23172;6
238.99001;293.51500;       0.17320;3.22867;6
238.66100;293.72500;-1.227721e-002;3.22968;6
239.81700;293.93500;       0.15051;3.22614;6
239.69099;294.14500; 4.915179e-002;3.22653;6
240.33501;294.35500; 6.345780e-002;3.22456;6
240.91100;294.56500;       0.13986;3.22279;6
240.82500;294.77500;-9.888465e-003;3.22306;6
241.97701;294.98500;       0.17678;3.21953;6
241.62900;295.19500; 4.981268e-004;3.22059;6
242.66400;295.40500;       0.12229;3.21742;6
242.77100;295.61500; 8.398895e-002;3.21709;6
243.12399;295.82500; 2.874832e-002;3.21601;6
243.97200;296.03500;       0.16320;3.21340;6
243.70900;296.24500;-1.752354e-002;3.21421;6
244.89799;296.45500;       0.16436;3.21055;6
244.64900;296.66500; 2.525947e-002;3.21132;6
245.47400;296.87500; 8.709929e-002;3.20878;6
245.85899;297.08500;       0.11863;3.20760;6
245.93700;297.29500; 1.270003e-003;3.20736;6
246.98801;297.50500;       0.17430;3.20412;6
246.64000;297.71500;-1.275570e-002;3.20519;6
247.77699;297.92500;       0.14219;3.20169;6
247.71100;298.13500; 5.734115e-002;3.20189;6
248.26300;298.34500; 4.971900e-002;3.20019;6
248.94000;298.55500;       0.14790;3.19810;6
248.78300;298.76500;-1.654162e-002;3.19858;6
249.95100;298.97500;       0.17173;3.19498;6
249.63300;299.18500; 5.617137e-003;3.19596;6
250.60500;299.39500;       0.10957;3.19295;6
250.79401;299.60500; 9.244654e-002;3.19237;6
251.06300;299.81500; 1.661105e-002;3.19154;6
251.98199;300.02500;       0.16652;3.18870;6
251.68100;300.23500;-2.143623e-002;3.18963;6
252.87000;300.44500;       0.15725;3.18595;6
252.66000;300.65500; 3.077262e-002;3.18660;6
253.40500;300.86500; 7.210621e-002;3.18429;6
253.88600;301.07500;       0.12671;3.18280;6
253.88100;301.28500;-9.402787e-003;3.18281;6
254.98399;301.49500;       0.17319;3.17939;6
254.63200;301.70500;-1.207812e-002;3.18049;6
255.72301;301.91500;       0.12914;3.17710;6
255.73599;302.12500; 6.561123e-002;3.17706;6
256.19699;302.33500; 3.464447e-002;3.17563;6
256.95599;302.54500;       0.15215;3.17327;6
256.74399;302.75500;-2.357404e-002;3.17393;6
257.93201;302.96500;       0.16623;3.17024;6
257.63901;303.17500; 8.497444e-003;3.17115;6
258.53900;303.38500; 9.373626e-002;3.16836;6
258.82599;303.59500;       0.10043;3.16746;6
258.99899;303.80500; 2.415037e-003;3.16692;6
259.98901;304.01500;       0.16707;3.16385;6
259.65601;304.22500;-2.522216e-002;3.16488;6
260.82501;304.43500;       0.14558;3.16124;6
260.68600;304.64500; 3.746929e-002;3.16168;6
261.33600;304.85500; 5.490766e-002;3.15965;6
261.90900;305.06500;       0.13078;3.15787;6
261.82800;305.27500;-2.127483e-002;3.15812;6
262.97198;305.48500;       0.16833;3.15456;6
262.62900;305.69500;-1.249824e-002;3.15563;6
263.66699;305.90500;       0.11340;3.15239;6
263.76501;306.11500; 7.088800e-002;3.15208;6
264.12900;306.32500; 1.727830e-002;3.15095;6
264.97000;306.53500;       0.15297;3.14833;6
264.70801;306.74500;-3.238391e-002;3.14914;6
265.89801;306.95500;       0.15453;3.14543;6
265.64999;307.16500; 1.011032e-002;3.14621;6
266.47699;307.37500; 7.553849e-002;3.14363;6
266.85400;307.58500;       0.10390;3.14245;6
266.94000;307.79500;-1.425601e-002;3.14218;6
267.99100;308.00500;       0.16218;3.13890;6
267.64099;308.21500;-3.105506e-002;3.13999;6
268.77600;308.42500;       0.12879;3.13645;6
268.71301;308.63500; 4.013019e-002;3.13664;6
269.27200;308.84500; 3.434620e-002;3.13490;6
269.93301;309.05500;       0.13027;3.13283;6
269.77399;309.26500;-3.752250e-002;3.13333;6
270.95099;309.47500;       0.15673;3.12965;6
270.63501;309.68500;-1.517149e-002;3.13064;6
271.60699;309.89500; 9.199355e-002;3.12760;6
271.79099;310.10500; 7.111638e-002;3.12702;6
272.06201;310.31500;-4.469999e-003;3.12618;6
272.98401;310.52500;       0.14802;3.12329;6
272.67700;310.73500;-4.611852e-002;3.12425;6
273.86600;310.94500;       0.13756;3.12053;6
273.66599;311.15500; 7.114572e-003;3.12116;6
274.40799;311.36500; 4.955994e-002;3.11884;6
274.88300;311.57500;       0.10108;3.11735;6
274.88599;311.78500;-3.536257e-002;3.11734;6
275.98099;311.99500;       0.14875;3.11392;6
275.63000;312.20500;-4.193283e-002;3.11502;6
276.72800;312.41500;       0.10527;3.11158;6
276.73499;312.62500; 3.528540e-002;3.11156;6
277.19901;312.83500; 5.941211e-003;3.11010;6
277.95499;313.04500;       0.12330;3.10774;6
277.74100;313.25500;-5.690628e-002;3.10841;6
278.93100;313.46500;       0.13651;3.10468;6
278.64001;313.67500;-2.629718e-002;3.10559;6
279.54001;313.88500; 6.167665e-002;3.10278;6
279.82300;314.09500; 6.467315e-002;3.10189;6
279.62701;314.19917;-4.744466e-002;3.10250;6